<?xml version="1.0" ?>
<!-- =================================================================================== -->
<!-- |    This document was autogenerated by xacro from /veriler/salih/Desktop/master_thesis/catkin_ws/src/horti_model/horti_description/urdf/horti.gazebo.urdf.xacro | -->
<!-- |    EDITING THIS FILE BY HAND IS NOT RECOMMENDED                                 | -->
<!-- =================================================================================== -->
<!-- =================================================================================== -->
<!-- |    This document was autogenerated by xacro from /home/rohit/workspace/phenorob_ws/src/robots/horti_description/horti_description/robots/horti.urdf.xacro | -->
<!-- |    EDITING THIS FILE BY HAND IS NOT RECOMMENDED                                 | -->
<!-- =================================================================================== -->
<robot name="horti">
  <!--
  Author: Rohit Menon <rohit.menon@uni-bonn.de>
  Contributers:
-->
  <!-- <link name="map"/> -->
  <link name="world"/>
  <!-- <joint name="world_joint" type="fixed" >
        <origin xyz="0 0 0" rpy="0 0 0" />
        <parent link="map" />
        <child link="world" />
    </joint> -->
  <gazebo>
    <plugin filename="libgazebo_ros_control.so" name="gazebo_ros_control">
      <robotNamespace>/</robotNamespace>
      <robotSimType>gazebo_ros_control/DefaultRobotHWSim</robotSimType>
      <legacyModeNS>true</legacyModeNS>
    </plugin>
  </gazebo>
  <material name="gray">
    <color rgba="0.4 0.4 0.4 1"/>
  </material>
  <material name="Black">
    <color rgba="0.0 0.0 0.0 1.0"/>
  </material>
  <material name="Red">
    <color rgba="0.8 0.0 0.0 1.0"/>
  </material>
  <material name="White">
    <color rgba="1.0 1.0 1.0 1.0"/>
  </material>
  <material name="Silver">
    <color rgba="0.753 0.753 0.753 1.0"/>
  </material>
  <material name="zed_mat">
    <color rgba="0.8 0.8 0.8 0.8"/>
  </material>
  <material name="zedm_mat">
    <color rgba="0 0 0 0.9"/>
  </material>
  <material name="zed2_mat">
    <color rgba="0.25 0.25 0.25 0.99"/>
  </material>
  <material name="zed2i_mat">
    <color rgba="0.25 0.25 0.25 0.99"/>
  </material>
  <!-- Trolley -->
  <material name="grey">
    <color rgba="0.5 0.5 0.5 1"/>
  </material>
  <!-- scissorlift  -->
  <link name="trolley_base_link">
    <visual>
      <geometry>
        <mesh filename="package://trolley_description/meshes/cart.stl" scale="0.001 0.001 0.001"/>
        <!-- For inertia computation, see: http://gazebosim.org/tutorials?tut=inertia&cat=build_robot
            Mesh Bounding Box Size 2.022500 0.778000 2.816000
            Mesh Bounding Box Diag 3.553259
            Mesh Volume is 0.257415
            Mesh Surface is 6.066614
            Thin shell barycenter -0.757169 0.073326 0.492247
            Center of Mass is -0.727568 0.022890 0.222313
            Inertia Tensor is :
            | 0.054632 0.002944 0.007421 |
            | 0.002944 0.106547 -0.006310 |
            | 0.007421 -0.006310 0.077534 |
            Principal axes are :
            | 0.950700 0.026703 0.308960 |
            | -0.085846 0.980013 0.179456 |
            | -0.297993 -0.197132 0.933991 |
            axis momenta are :
            | 0.052040 0.107896 0.078777 |
            -->
      </geometry>
      <origin rpy="0 0 0" xyz="0 0 0"/>
      <material name="grey"/>
    </visual>
  </link>
  <joint name="trolley_platform_joint" type="fixed">
    <origin rpy="0 0 0" xyz="0.0 0.0 1.0969001"/>
    <axis xyz="0 0 1"/>
    <limit effort="1000" lower="0" upper="2.2" velocity="1000.00"/>
    <parent link="trolley_base_link"/>
    <child link="trolley_platform_link"/>
  </joint>
  <link name="trolley_platform_link">
    <visual>
      <geometry>
        <mesh filename="package://trolley_description/meshes/platform.stl" scale="0.001 0.001 0.001"/>
        <!-- For inertia computation, see: http://gazebosim.org/tutorials?tut=inertia&cat=build_robot
            MeshLab Output:
            Mesh Bounding Box Size 1.445693 0.420000 0.147347
            Mesh Bounding Box Diag 1.512660
            Mesh Volume is 0.063594
            Mesh Surface is 1.832135
            Thin shell barycenter -0.722672 -0.000002 -0.031958
            Center of Mass is -0.722708 -0.000002 -0.039040
            Inertia Tensor is :
            | 0.001112 -0.000000 0.000056 |
            | -0.000000 0.011134 0.000000 |
            | 0.000056 0.000000 0.012108 |
            Principal axes are :
            | 0.999987 -0.000000 0.005086 |
            | 0.000000 1.000000 0.000002 |
            | -0.005086 -0.000002 0.999987 |
            axis momenta are :
            | 0.001112 0.011134 0.012109 |
            -->
      </geometry>
      <origin rpy="0 0 0" xyz="0 0 0"/>
      <material name="grey"/>
    </visual>
  </link>
  <!--joint name="platform_base_to_control_box" type="fixed">
    <origin xyz="1.19 0 0.04" rpy="0 0 0"/>
    <parent link="platform_base"/>
    <child link="control_box"/>
  </joint>


  <link name="control_box">
    <visual>
      <origin xyz="0.115 0  0.225" rpy="0 0 0" />
      <geometry>
        <box size="0.23 0.45 0.4" />
      </geometry>
      <material name="Cyan">
        <color rgba="0 1.0 1.0 1.0"/>
      </material>
    </visual>
  </link-->
  <!-- Camera fixed joints -->
  <joint name="base_link_to_cam0" type="fixed">
    <origin rpy="1.570796327 0 1.570796327" xyz="1.860 -0.238319 0.6835"/>
    <parent link="trolley_base_link"/>
    <child link="camera0_link"/>
  </joint>
  <link name="camera0_link">
  </link>
  <joint name="base_link_to_cam1" type="fixed">
    <origin rpy="1.570796327 0 1.570796327" xyz="1.860 -0.237319 1.3475"/>
    <parent link="trolley_base_link"/>
    <child link="camera1_link"/>
  </joint>
  <link name="camera1_link">
  </link>
  <joint name="base_link_to_cam2" type="fixed">
    <origin rpy="1.570796327 0 1.570796327" xyz="1.860 -0.237319 2.0115"/>
    <parent link="trolley_base_link"/>
    <child link="camera2_link"/>
  </joint>
  <link name="camera2_link">
  </link>
  <joint name="base_link_to_cam3" type="fixed">
    <origin rpy="1.570796327 0 1.570796327" xyz="1.860 -0.237319 2.6755"/>
    <parent link="trolley_base_link"/>
    <child link="camera3_link"/>
  </joint>
  <link name="camera3_link">
  </link>
  <joint name="base_link_to_tracker" type="fixed">
    <origin rpy="0 0 1.570796327" xyz="1.815 -0.237319 1.3475"/>
    <parent link="trolley_base_link"/>
    <child link="tracker"/>
  </joint>
  <link name="tracker">
  </link>
  <joint name="base_link_joint" type="fixed">
    <origin rpy="0.0 0 1.5708" xyz="0.0 0 0.1"/>
    <parent link="world"/>
    <child link="trolley_base_link"/>
  </joint>
  <link name="arm_holder_link">
    <visual>
      <material name="gray"/>
      <origin rpy="0 0 0" xyz="0 0 -0.015"/>
      <geometry>
        <box size="1.44 0.42 0.03"/>
      </geometry>
    </visual>
    <collision>
      <origin rpy="0 0 0" xyz="0 0 -0.015"/>
      <geometry>
        <box size="1.44 0.42 0.03"/>
      </geometry>
    </collision>
  </link>
  <joint name="arm_holder_joint" type="fixed">
    <origin rpy="0 0 0" xyz="-0.72 0 0.08"/>
    <parent link="trolley_platform_link"/>
    <child link="arm_holder_link"/>
  </joint>
  <link name="trolley_back_link">
    <collision>
      <origin rpy="0 0 0" xyz="0 0 0.75"/>
      <geometry>
        <box size="1.44 0.001 1.5"/>
      </geometry>
    </collision>
  </link>
  <joint name="trolley_back_joint" type="fixed">
    <origin rpy="0 0 0" xyz="-0.72 0.26 0"/>
    <parent link="trolley_platform_link"/>
    <child link="trolley_back_link"/>
  </joint>
  <link name="power_link">
    <visual>
      <material name="gray"/>
      <origin rpy="0 0 0" xyz="0 -0.05 0.175"/>
      <geometry>
        <box size="0.45 0.1 0.35"/>
      </geometry>
    </visual>
    <collision>
      <origin rpy="0 0 0" xyz="0 -0.05 0.175"/>
      <geometry>
        <box size="0.45 0.1 0.35"/>
      </geometry>
    </collision>
  </link>
  <joint name="power_joint" type="fixed">
    <parent link="trolley_base_link"/>
    <child link="power_link"/>
    <origin rpy="0 0 0" xyz="-0.72 -0.22 0.18"/>
  </joint>
  <link name="base_control_link">
    <visual>
      <material name="gray"/>
      <origin rpy="0 0 0" xyz="0 -0.075 0.06"/>
      <geometry>
        <box size="0.3 0.15 0.12"/>
      </geometry>
    </visual>
    <collision>
      <origin rpy="0 0 0" xyz="0 -0.075 0.06"/>
      <geometry>
        <box size="0.3 0.15 0.12"/>
      </geometry>
    </collision>
  </link>
  <joint name="base_control_joint" type="fixed">
    <parent link="trolley_base_link"/>
    <child link="base_control_link"/>
    <origin rpy="0 0 0" xyz="-0.21999999999999997 -0.22 0.18"/>
  </joint>
  <link name="basket_link">
    <visual>
      <material name="gray"/>
      <origin rpy="0 0 0" xyz="0 0 0.11499999999999999"/>
      <geometry>
        <box size="0.4 0.15 0.15"/>
      </geometry>
    </visual>
    <!-- <collision>
            <origin xyz="0 0 ${basket_height / 2 + 0.04}" rpy="0 0 0" />
            <geometry>
                <box size="${basket_length} ${basket_width} ${basket_height}" />
            </geometry>
        </collision> -->
  </link>
  <joint name="basket_joint" type="fixed">
    <parent link="trolley_platform_link"/>
    <child link="basket_link"/>
    <origin rpy="3.141592653589793 0 0" xyz="-1.24 -0.295 0.14"/>
  </joint>
  <link name="arm_right_controller_link">
    <visual>
      <material name="gray"/>
      <origin rpy="0 0 0" xyz="0 0 0.06"/>
      <geometry>
        <box size="0.15 0.32 0.12"/>
      </geometry>
    </visual>
    <collision>
      <origin rpy="0 0 0" xyz="0 0 0.06"/>
      <geometry>
        <box size="0.15 0.32 0.12"/>
      </geometry>
    </collision>
  </link>
  <joint name="arm_right_controller_joint" type="fixed">
    <origin rpy="0 0 0" xyz=" -1.315 0 0.08"/>
    <child link="arm_right_controller_link"/>
    <parent link="trolley_platform_link"/>
  </joint>
  <link name="arm_left_controller_link">
    <visual>
      <material name="gray"/>
      <origin rpy="0 0 0" xyz="0 0 0.06"/>
      <geometry>
        <box size="0.15 0.32 0.12"/>
      </geometry>
    </visual>
    <collision>
      <origin rpy="0 0 0" xyz="0 0 0.06"/>
      <geometry>
        <box size="0.15 0.32 0.12"/>
      </geometry>
    </collision>
  </link>
  <joint name="arm_left_controller_joint" type="fixed">
    <origin rpy="0 0 0" xyz=" -0.125 0 0.08"/>
    <child link="arm_left_controller_link"/>
    <parent link="trolley_platform_link"/>
  </joint>
  <link name="trolley_local_link"/>
  <joint name="trolley_local_joint" type="fixed">
    <origin rpy="0 0 3.141592653589793" xyz="0 0 0"/>
    <parent link="trolley_platform_link"/>
    <child link="trolley_local_link"/>
  </joint>
  <!-- Arms -->
  <!--
  Author: Jimy Zhang <jimy.zhang@ufactory.cc> <jimy92@163.com>
  Contributers:
-->
  <joint name="arm_right_world_joint" type="fixed">
    <parent link="arm_holder_link"/>
    <child link="arm_right_link_base"/>
    <origin rpy="0 0 -1.5707963267948966" xyz="-0.35 -0.1 0.0"/>
  </joint>
  <!-- collision_type values: visual, reduced_mesh_auto, reduced_mesh_manual_quality, reduced_mesh_manual_performance, spheres, shapes, capsules-->
  <link name="arm_right_link_base">
    <inertial>
      <origin rpy="0 0 0" xyz="-0.021131 -0.0016302 0.056488"/>
      <mass value="2.612"/>
      <inertia ixx="0.0030595" ixy="0.00012259" ixz="-0.00062705" iyy="0.0037783" iyz="0.00027023" izz="0.0020125"/>
    </inertial>
    <visual>
      <origin rpy="0 0 0" xyz="0 0 0"/>
      <geometry>
        <mesh filename="package://horti_description/meshes/xarm7/visual/link_base.STL"/>
      </geometry>
      <material name="White"/>
    </visual>
    <collision>
      <geometry>
        <mesh filename="package://horti_description/meshes/xarm7/visual/link_base.STL"/>
      </geometry>
    </collision>
  </link>
  <link name="arm_right_link1">
    <inertial>
      <origin rpy="0 0 0" xyz="0.00013 0.0301 -0.012"/>
      <mass value="2.459"/>
      <inertia ixx="0.005795" ixy="-1.078E-05" ixz="-2.63E-05" iyy="0.004969" iyz="0.000911" izz="0.003428"/>
    </inertial>
    <visual>
      <origin rpy="0 0 0" xyz="0 0 0"/>
      <geometry>
        <mesh filename="package://horti_description/meshes/xarm7/visual/link1.STL"/>
      </geometry>
      <material name="White"/>
    </visual>
    <collision>
      <geometry>
        <mesh filename="package://horti_description/meshes/xarm7/visual/link1.STL"/>
      </geometry>
    </collision>
  </link>
  <joint name="arm_right_joint1" type="revolute">
    <origin rpy="0 0 0" xyz="0 0 0.267"/>
    <parent link="arm_right_link_base"/>
    <child link="arm_right_link1"/>
    <axis xyz="0 0 1"/>
    <limit effort="50" lower="-3.1101767270538954" upper="3.1101767270538954" velocity="3.14"/>
    <dynamics damping="10" friction="1"/>
  </joint>
  <link name="arm_right_link2">
    <inertial>
      <origin rpy="0 0 0" xyz="0.0002 -0.12964 0.01692"/>
      <mass value="1.916"/>
      <inertia ixx="0.0097184" ixy="1.0E-06" ixz="-4.83E-06" iyy="0.0038705" iyz="0.0032" izz="0.007672"/>
    </inertial>
    <visual>
      <origin rpy="0 0 0" xyz="0 0 0"/>
      <geometry>
        <mesh filename="package://horti_description/meshes/xarm7/visual/link2.STL"/>
      </geometry>
      <material name="White"/>
    </visual>
    <collision>
      <geometry>
        <mesh filename="package://horti_description/meshes/xarm7/visual/link2.STL"/>
      </geometry>
    </collision>
  </link>
  <joint name="arm_right_joint2" type="revolute">
    <origin rpy="-1.5708 0 0" xyz="0 0 0"/>
    <parent link="arm_right_link1"/>
    <child link="arm_right_link2"/>
    <axis xyz="0 0 1"/>
    <limit effort="50" lower="-2.18" upper="2.18" velocity="3.14"/>
    <dynamics damping="10" friction="1"/>
  </joint>
  <link name="arm_right_link3">
    <inertial>
      <origin rpy="0 0 0" xyz="0.04676 -0.02526 -0.00746"/>
      <mass value="1.6854"/>
      <inertia ixx="0.0031588" ixy="-3.1443E-04" ixz="5.8658E-04" iyy="0.002682" iyz="-3.469E-04" izz="0.0027105"/>
    </inertial>
    <visual>
      <origin rpy="0 0 0" xyz="0 0 0"/>
      <geometry>
        <mesh filename="package://horti_description/meshes/xarm7/visual/link3.STL"/>
      </geometry>
      <material name="White"/>
    </visual>
    <collision>
      <geometry>
        <mesh filename="package://horti_description/meshes/xarm7/visual/link3.STL"/>
      </geometry>
    </collision>
  </link>
  <joint name="arm_right_joint3" type="revolute">
    <origin rpy="1.5708 0 0" xyz="0 -0.293 0"/>
    <parent link="arm_right_link2"/>
    <child link="arm_right_link3"/>
    <axis xyz="0 0 1"/>
    <limit effort="30" lower="-3.1101767270538954" upper="3.1101767270538954" velocity="3.14"/>
    <dynamics damping="5" friction="1"/>
  </joint>
  <link name="arm_right_link4">
    <inertial>
      <origin rpy="0 0 0" xyz="0.07066 -0.11664 0.0117"/>
      <mass value="1.774"/>
      <inertia ixx="0.005967" ixy="-0.001382" ixz="-0.00088544" iyy="0.00363897" iyz="0.0017806" izz="0.005509226"/>
    </inertial>
    <visual>
      <origin rpy="0 0 0" xyz="0 0 0"/>
      <geometry>
        <mesh filename="package://horti_description/meshes/xarm7/visual/link4.STL"/>
      </geometry>
      <material name="White"/>
    </visual>
    <collision>
      <geometry>
        <mesh filename="package://horti_description/meshes/xarm7/visual/link4.STL"/>
      </geometry>
    </collision>
  </link>
  <joint name="arm_right_joint4" type="revolute">
    <origin rpy="1.5708 0 0" xyz="0.0525 0 0"/>
    <parent link="arm_right_link3"/>
    <child link="arm_right_link4"/>
    <axis xyz="0 0 1"/>
    <limit effort="30" lower="-0.11" upper="3.1101767270538954" velocity="3.14"/>
    <dynamics damping="5" friction="1"/>
  </joint>
  <link name="arm_right_link5">
    <inertial>
      <origin rpy="0 0 0" xyz="-0.00031 0.01558 -0.0253"/>
      <mass value="1.357"/>
      <inertia ixx="0.005396" ixy="-1.53E-05" ixz="-6.7E-07" iyy="0.005" iyz="0.00020544" izz="0.00138734"/>
    </inertial>
    <visual>
      <origin rpy="0 0 0" xyz="0 0 0"/>
      <geometry>
        <mesh filename="package://horti_description/meshes/xarm7/visual/link5.STL"/>
      </geometry>
      <material name="White"/>
    </visual>
    <collision>
      <geometry>
        <mesh filename="package://horti_description/meshes/xarm7/visual/link5.STL"/>
      </geometry>
    </collision>
  </link>
  <joint name="arm_right_joint5" type="revolute">
    <origin rpy="1.5708 0 0" xyz="0.0775 -0.3425 0"/>
    <parent link="arm_right_link4"/>
    <child link="arm_right_link5"/>
    <axis xyz="0 0 1"/>
    <limit effort="30" lower="-3.1101767270538954" upper="3.1101767270538954" velocity="3.14"/>
    <dynamics damping="5" friction="1"/>
  </joint>
  <link name="arm_right_link6">
    <inertial>
      <origin rpy="0 0 0" xyz="0.065 0.03336 0.02131"/>
      <mass value="1.362"/>
      <inertia ixx="0.0015057" ixy="0.000496735" ixz="-2.9968E-04" iyy="0.0019297" iyz="-1.5E-04" izz="0.0024"/>
    </inertial>
    <visual>
      <origin rpy="0 0 0" xyz="0 0 0"/>
      <geometry>
        <mesh filename="package://horti_description/meshes/xarm7/visual/link6.STL"/>
      </geometry>
      <material name="White"/>
    </visual>
    <collision>
      <geometry>
        <mesh filename="package://horti_description/meshes/xarm7/visual/link6.STL"/>
      </geometry>
    </collision>
  </link>
  <joint name="arm_right_joint6" type="revolute">
    <origin rpy="1.5708 0 0" xyz="0 0 0"/>
    <parent link="arm_right_link5"/>
    <child link="arm_right_link6"/>
    <axis xyz="0 0 1"/>
    <limit effort="20" lower="-1.75" upper="3.1101767270538954" velocity="3.14"/>
    <dynamics damping="2" friction="1"/>
  </joint>
  <link name="arm_right_link7">
    <inertial>
      <origin rpy="0 0 0" xyz="0 -0.00677 -0.01098"/>
      <mass value="0.17"/>
      <inertia ixx="9.3E-05" ixy="0.0" ixz="0.0" iyy="5.87E-05" iyz="3.6E-06" izz="1.32E-04"/>
    </inertial>
    <visual>
      <origin rpy="0 0 0" xyz="0 0 0"/>
      <geometry>
        <mesh filename="package://horti_description/meshes/xarm7/visual/link7.STL"/>
      </geometry>
      <material name="Silver"/>
    </visual>
    <collision>
      <geometry>
        <mesh filename="package://horti_description/meshes/xarm7/visual/link7.STL"/>
      </geometry>
    </collision>
  </link>
  <joint name="arm_right_joint7" type="revolute">
    <origin rpy="-1.5708 0 0" xyz="0.076 0.097 0"/>
    <parent link="arm_right_link6"/>
    <child link="arm_right_link7"/>
    <axis xyz="0 0 1"/>
    <limit effort="20" lower="-3.1101767270538954" upper="3.1101767270538954" velocity="3.14"/>
    <dynamics damping="2" friction="1"/>
  </joint>
  <link name="arm_right_link_eef"/>
  <joint name="arm_right_joint_eef" type="fixed">
    <origin rpy="0 0 0" xyz="0 0 0"/>
    <parent link="arm_right_link7"/>
    <child link="arm_right_link_eef"/>
  </joint>
  <transmission name="arm_right_tran1">
    <type>transmission_interface/SimpleTransmission</type>
    <joint name="arm_right_joint1">
      <hardwareInterface>hardware_interface/PositionJointInterface</hardwareInterface>
    </joint>
    <actuator name="arm_right_motor1">
      <hardwareInterface>hardware_interface/PositionJointInterface</hardwareInterface>
      <mechanicalReduction>100</mechanicalReduction>
    </actuator>
  </transmission>
  <transmission name="arm_right_tran2">
    <type>transmission_interface/SimpleTransmission</type>
    <joint name="arm_right_joint2">
      <hardwareInterface>hardware_interface/PositionJointInterface</hardwareInterface>
    </joint>
    <actuator name="arm_right_motor2">
      <hardwareInterface>hardware_interface/PositionJointInterface</hardwareInterface>
      <mechanicalReduction>100</mechanicalReduction>
    </actuator>
  </transmission>
  <transmission name="arm_right_tran3">
    <type>transmission_interface/SimpleTransmission</type>
    <joint name="arm_right_joint3">
      <hardwareInterface>hardware_interface/PositionJointInterface</hardwareInterface>
    </joint>
    <actuator name="arm_right_motor3">
      <hardwareInterface>hardware_interface/PositionJointInterface</hardwareInterface>
      <mechanicalReduction>100</mechanicalReduction>
    </actuator>
  </transmission>
  <transmission name="arm_right_tran4">
    <type>transmission_interface/SimpleTransmission</type>
    <joint name="arm_right_joint4">
      <hardwareInterface>hardware_interface/PositionJointInterface</hardwareInterface>
    </joint>
    <actuator name="arm_right_motor3">
      <hardwareInterface>hardware_interface/PositionJointInterface</hardwareInterface>
      <mechanicalReduction>100</mechanicalReduction>
    </actuator>
  </transmission>
  <transmission name="arm_right_tran5">
    <type>transmission_interface/SimpleTransmission</type>
    <joint name="arm_right_joint5">
      <hardwareInterface>hardware_interface/PositionJointInterface</hardwareInterface>
    </joint>
    <actuator name="arm_right_motor5">
      <hardwareInterface>hardware_interface/PositionJointInterface</hardwareInterface>
      <mechanicalReduction>100</mechanicalReduction>
    </actuator>
  </transmission>
  <transmission name="arm_right_tran6">
    <type>transmission_interface/SimpleTransmission</type>
    <joint name="arm_right_joint6">
      <hardwareInterface>hardware_interface/PositionJointInterface</hardwareInterface>
    </joint>
    <actuator name="arm_right_motor6">
      <hardwareInterface>hardware_interface/PositionJointInterface</hardwareInterface>
      <mechanicalReduction>100</mechanicalReduction>
    </actuator>
  </transmission>
  <transmission name="arm_right_tran7">
    <type>transmission_interface/SimpleTransmission</type>
    <joint name="arm_right_joint7">
      <hardwareInterface>hardware_interface/PositionJointInterface</hardwareInterface>
    </joint>
    <actuator name="arm_right_motor7">
      <hardwareInterface>hardware_interface/PositionJointInterface</hardwareInterface>
      <mechanicalReduction>100</mechanicalReduction>
    </actuator>
  </transmission>
  <gazebo reference="arm_right_link_base">
    <selfCollide>true</selfCollide>
  </gazebo>
  <gazebo reference="arm_right_link1">
    <selfCollide>true</selfCollide>
  </gazebo>
  <gazebo reference="arm_right_link2">
    <selfCollide>true</selfCollide>
  </gazebo>
  <gazebo reference="arm_right_link3">
    <selfCollide>true</selfCollide>
  </gazebo>
  <gazebo reference="arm_right_link4">
    <selfCollide>true</selfCollide>
  </gazebo>
  <gazebo reference="arm_right_link5">
    <selfCollide>true</selfCollide>
  </gazebo>
  <gazebo reference="arm_right_link6">
    <selfCollide>true</selfCollide>
  </gazebo>
  <gazebo reference="arm_right_link7">
    <selfCollide>true</selfCollide>
  </gazebo>
  <!--
  Author: Jimy Zhang <jimy.zhang@ufactory.cc> <jimy92@163.com>
  Contributers:
-->
  <joint name="arm_left_world_joint" type="fixed">
    <parent link="arm_holder_link"/>
    <child link="arm_left_link_base"/>
    <origin rpy="0 0.0 -1.5707963267948966" xyz="0.35 -0.1 0.0"/>
  </joint>
  <!-- collision_type values: visual, reduced_mesh_auto, reduced_mesh_manual_quality, reduced_mesh_manual_performance, spheres, shapes, capsules-->
  <link name="arm_left_link_base">
    <inertial>
      <origin rpy="0 0 0" xyz="-0.021131 -0.0016302 0.056488"/>
      <mass value="2.612"/>
      <inertia ixx="0.0030595" ixy="0.00012259" ixz="-0.00062705" iyy="0.0037783" iyz="0.00027023" izz="0.0020125"/>
    </inertial>
    <visual>
      <origin rpy="0 0 0" xyz="0 0 0"/>
      <geometry>
        <mesh filename="package://horti_description/meshes/xarm7/visual/link_base.STL"/>
      </geometry>
      <material name="White"/>
    </visual>
    <collision>
      <geometry>
        <mesh filename="package://horti_description/meshes/xarm7/visual/link_base.STL"/>
      </geometry>
    </collision>
  </link>
  <link name="arm_left_link1">
    <inertial>
      <origin rpy="0 0 0" xyz="0.00013 0.0301 -0.012"/>
      <mass value="2.459"/>
      <inertia ixx="0.005795" ixy="-1.078E-05" ixz="-2.63E-05" iyy="0.004969" iyz="0.000911" izz="0.003428"/>
    </inertial>
    <visual>
      <origin rpy="0 0 0" xyz="0 0 0"/>
      <geometry>
        <mesh filename="package://horti_description/meshes/xarm7/visual/link1.STL"/>
      </geometry>
      <material name="White"/>
    </visual>
    <collision>
      <geometry>
        <mesh filename="package://horti_description/meshes/xarm7/visual/link1.STL"/>
      </geometry>
    </collision>
  </link>
  <joint name="arm_left_joint1" type="revolute">
    <origin rpy="0 0 0" xyz="0 0 0.267"/>
    <parent link="arm_left_link_base"/>
    <child link="arm_left_link1"/>
    <axis xyz="0 0 1"/>
    <limit effort="50" lower="-3.1101767270538954" upper="3.1101767270538954" velocity="3.14"/>
    <dynamics damping="10" friction="1"/>
  </joint>
  <link name="arm_left_link2">
    <inertial>
      <origin rpy="0 0 0" xyz="0.0002 -0.12964 0.01692"/>
      <mass value="1.916"/>
      <inertia ixx="0.0097184" ixy="1.0E-06" ixz="-4.83E-06" iyy="0.0038705" iyz="0.0032" izz="0.007672"/>
    </inertial>
    <visual>
      <origin rpy="0 0 0" xyz="0 0 0"/>
      <geometry>
        <mesh filename="package://horti_description/meshes/xarm7/visual/link2.STL"/>
      </geometry>
      <material name="White"/>
    </visual>
    <collision>
      <geometry>
        <mesh filename="package://horti_description/meshes/xarm7/visual/link2.STL"/>
      </geometry>
    </collision>
  </link>
  <joint name="arm_left_joint2" type="revolute">
    <origin rpy="-1.5708 0 0" xyz="0 0 0"/>
    <parent link="arm_left_link1"/>
    <child link="arm_left_link2"/>
    <axis xyz="0 0 1"/>
    <limit effort="50" lower="-2.18" upper="2.18" velocity="3.14"/>
    <dynamics damping="10" friction="1"/>
  </joint>
  <link name="arm_left_link3">
    <inertial>
      <origin rpy="0 0 0" xyz="0.04676 -0.02526 -0.00746"/>
      <mass value="1.6854"/>
      <inertia ixx="0.0031588" ixy="-3.1443E-04" ixz="5.8658E-04" iyy="0.002682" iyz="-3.469E-04" izz="0.0027105"/>
    </inertial>
    <visual>
      <origin rpy="0 0 0" xyz="0 0 0"/>
      <geometry>
        <mesh filename="package://horti_description/meshes/xarm7/visual/link3.STL"/>
      </geometry>
      <material name="White"/>
    </visual>
    <collision>
      <geometry>
        <mesh filename="package://horti_description/meshes/xarm7/visual/link3.STL"/>
      </geometry>
    </collision>
  </link>
  <joint name="arm_left_joint3" type="revolute">
    <origin rpy="1.5708 0 0" xyz="0 -0.293 0"/>
    <parent link="arm_left_link2"/>
    <child link="arm_left_link3"/>
    <axis xyz="0 0 1"/>
    <limit effort="30" lower="-3.1101767270538954" upper="3.1101767270538954" velocity="3.14"/>
    <dynamics damping="5" friction="1"/>
  </joint>
  <link name="arm_left_link4">
    <inertial>
      <origin rpy="0 0 0" xyz="0.07066 -0.11664 0.0117"/>
      <mass value="1.774"/>
      <inertia ixx="0.005967" ixy="-0.001382" ixz="-0.00088544" iyy="0.00363897" iyz="0.0017806" izz="0.005509226"/>
    </inertial>
    <visual>
      <origin rpy="0 0 0" xyz="0 0 0"/>
      <geometry>
        <mesh filename="package://horti_description/meshes/xarm7/visual/link4.STL"/>
      </geometry>
      <material name="White"/>
    </visual>
    <collision>
      <geometry>
        <mesh filename="package://horti_description/meshes/xarm7/visual/link4.STL"/>
      </geometry>
    </collision>
  </link>
  <joint name="arm_left_joint4" type="revolute">
    <origin rpy="1.5708 0 0" xyz="0.0525 0 0"/>
    <parent link="arm_left_link3"/>
    <child link="arm_left_link4"/>
    <axis xyz="0 0 1"/>
    <limit effort="30" lower="-0.11" upper="3.1101767270538954" velocity="3.14"/>
    <dynamics damping="5" friction="1"/>
  </joint>
  <link name="arm_left_link5">
    <inertial>
      <origin rpy="0 0 0" xyz="-0.00031 0.01558 -0.0253"/>
      <mass value="1.357"/>
      <inertia ixx="0.005396" ixy="-1.53E-05" ixz="-6.7E-07" iyy="0.005" iyz="0.00020544" izz="0.00138734"/>
    </inertial>
    <visual>
      <origin rpy="0 0 0" xyz="0 0 0"/>
      <geometry>
        <mesh filename="package://horti_description/meshes/xarm7/visual/link5.STL"/>
      </geometry>
      <material name="White"/>
    </visual>
    <collision>
      <geometry>
        <mesh filename="package://horti_description/meshes/xarm7/visual/link5.STL"/>
      </geometry>
    </collision>
  </link>
  <joint name="arm_left_joint5" type="revolute">
    <origin rpy="1.5708 0 0" xyz="0.0775 -0.3425 0"/>
    <parent link="arm_left_link4"/>
    <child link="arm_left_link5"/>
    <axis xyz="0 0 1"/>
    <limit effort="30" lower="-3.1101767270538954" upper="3.1101767270538954" velocity="3.14"/>
    <dynamics damping="5" friction="1"/>
  </joint>
  <link name="arm_left_link6">
    <inertial>
      <origin rpy="0 0 0" xyz="0.065 0.03336 0.02131"/>
      <mass value="1.362"/>
      <inertia ixx="0.0015057" ixy="0.000496735" ixz="-2.9968E-04" iyy="0.0019297" iyz="-1.5E-04" izz="0.0024"/>
    </inertial>
    <visual>
      <origin rpy="0 0 0" xyz="0 0 0"/>
      <geometry>
        <mesh filename="package://horti_description/meshes/xarm7/visual/link6.STL"/>
      </geometry>
      <material name="White"/>
    </visual>
    <collision>
      <geometry>
        <mesh filename="package://horti_description/meshes/xarm7/visual/link6.STL"/>
      </geometry>
    </collision>
  </link>
  <joint name="arm_left_joint6" type="revolute">
    <origin rpy="1.5708 0 0" xyz="0 0 0"/>
    <parent link="arm_left_link5"/>
    <child link="arm_left_link6"/>
    <axis xyz="0 0 1"/>
    <limit effort="20" lower="-1.75" upper="3.1101767270538954" velocity="3.14"/>
    <dynamics damping="2" friction="1"/>
  </joint>
  <link name="arm_left_link7">
    <inertial>
      <origin rpy="0 0 0" xyz="0 -0.00677 -0.01098"/>
      <mass value="0.17"/>
      <inertia ixx="9.3E-05" ixy="0.0" ixz="0.0" iyy="5.87E-05" iyz="3.6E-06" izz="1.32E-04"/>
    </inertial>
    <visual>
      <origin rpy="0 0 0" xyz="0 0 0"/>
      <geometry>
        <mesh filename="package://horti_description/meshes/xarm7/visual/link7.STL"/>
      </geometry>
      <material name="Silver"/>
    </visual>
    <collision>
      <geometry>
        <mesh filename="package://horti_description/meshes/xarm7/visual/link7.STL"/>
      </geometry>
    </collision>
  </link>
  <joint name="arm_left_joint7" type="revolute">
    <origin rpy="-1.5708 0 0" xyz="0.076 0.097 0"/>
    <parent link="arm_left_link6"/>
    <child link="arm_left_link7"/>
    <axis xyz="0 0 1"/>
    <limit effort="20" lower="-3.1101767270538954" upper="3.1101767270538954" velocity="3.14"/>
    <dynamics damping="2" friction="1"/>
  </joint>
  <link name="arm_left_link_eef"/>
  <joint name="arm_left_joint_eef" type="fixed">
    <origin rpy="0 0 0" xyz="0 0 0"/>
    <parent link="arm_left_link7"/>
    <child link="arm_left_link_eef"/>
  </joint>
  <transmission name="arm_left_tran1">
    <type>transmission_interface/SimpleTransmission</type>
    <joint name="arm_left_joint1">
      <hardwareInterface>hardware_interface/PositionJointInterface</hardwareInterface>
    </joint>
    <actuator name="arm_left_motor1">
      <hardwareInterface>hardware_interface/PositionJointInterface</hardwareInterface>
      <mechanicalReduction>100</mechanicalReduction>
    </actuator>
  </transmission>
  <transmission name="arm_left_tran2">
    <type>transmission_interface/SimpleTransmission</type>
    <joint name="arm_left_joint2">
      <hardwareInterface>hardware_interface/PositionJointInterface</hardwareInterface>
    </joint>
    <actuator name="arm_left_motor2">
      <hardwareInterface>hardware_interface/PositionJointInterface</hardwareInterface>
      <mechanicalReduction>100</mechanicalReduction>
    </actuator>
  </transmission>
  <transmission name="arm_left_tran3">
    <type>transmission_interface/SimpleTransmission</type>
    <joint name="arm_left_joint3">
      <hardwareInterface>hardware_interface/PositionJointInterface</hardwareInterface>
    </joint>
    <actuator name="arm_left_motor3">
      <hardwareInterface>hardware_interface/PositionJointInterface</hardwareInterface>
      <mechanicalReduction>100</mechanicalReduction>
    </actuator>
  </transmission>
  <transmission name="arm_left_tran4">
    <type>transmission_interface/SimpleTransmission</type>
    <joint name="arm_left_joint4">
      <hardwareInterface>hardware_interface/PositionJointInterface</hardwareInterface>
    </joint>
    <actuator name="arm_left_motor3">
      <hardwareInterface>hardware_interface/PositionJointInterface</hardwareInterface>
      <mechanicalReduction>100</mechanicalReduction>
    </actuator>
  </transmission>
  <transmission name="arm_left_tran5">
    <type>transmission_interface/SimpleTransmission</type>
    <joint name="arm_left_joint5">
      <hardwareInterface>hardware_interface/PositionJointInterface</hardwareInterface>
    </joint>
    <actuator name="arm_left_motor5">
      <hardwareInterface>hardware_interface/PositionJointInterface</hardwareInterface>
      <mechanicalReduction>100</mechanicalReduction>
    </actuator>
  </transmission>
  <transmission name="arm_left_tran6">
    <type>transmission_interface/SimpleTransmission</type>
    <joint name="arm_left_joint6">
      <hardwareInterface>hardware_interface/PositionJointInterface</hardwareInterface>
    </joint>
    <actuator name="arm_left_motor6">
      <hardwareInterface>hardware_interface/PositionJointInterface</hardwareInterface>
      <mechanicalReduction>100</mechanicalReduction>
    </actuator>
  </transmission>
  <transmission name="arm_left_tran7">
    <type>transmission_interface/SimpleTransmission</type>
    <joint name="arm_left_joint7">
      <hardwareInterface>hardware_interface/PositionJointInterface</hardwareInterface>
    </joint>
    <actuator name="arm_left_motor7">
      <hardwareInterface>hardware_interface/PositionJointInterface</hardwareInterface>
      <mechanicalReduction>100</mechanicalReduction>
    </actuator>
  </transmission>
  <gazebo reference="arm_left_link_base">
    <selfCollide>true</selfCollide>
  </gazebo>
  <gazebo reference="arm_left_link1">
    <selfCollide>true</selfCollide>
  </gazebo>
  <gazebo reference="arm_left_link2">
    <selfCollide>true</selfCollide>
  </gazebo>
  <gazebo reference="arm_left_link3">
    <selfCollide>true</selfCollide>
  </gazebo>
  <gazebo reference="arm_left_link4">
    <selfCollide>true</selfCollide>
  </gazebo>
  <gazebo reference="arm_left_link5">
    <selfCollide>true</selfCollide>
  </gazebo>
  <gazebo reference="arm_left_link6">
    <selfCollide>true</selfCollide>
  </gazebo>
  <gazebo reference="arm_left_link7">
    <selfCollide>true</selfCollide>
  </gazebo>
  <!-- FT-Sensors -->
  <link name="arm_right_ft_link">
    <visual>
      <origin rpy="0 0 0" xyz="0 0 -0.0111"/>
      <material name="gray"/>
      <geometry>
        <cylinder length="0.0222" radius="0.04"/>
      </geometry>
    </visual>
    <collision>
      <origin rpy="0 0 0" xyz="0 0 -0.0111"/>
      <material name="gray"/>
      <geometry>
        <cylinder length="0.0222" radius="0.04"/>
      </geometry>
    </collision>
  </link>
  <joint name="arm_right_ft_joint" type="fixed">
    <origin rpy="0 0 0" xyz="0 0 0.0222"/>
    <parent link="arm_right_link7"/>
    <child link="arm_right_ft_link"/>
  </joint>
  <link name="arm_left_ft_link">
    <visual>
      <origin rpy="0 0 0" xyz="0 0 -0.0111"/>
      <material name="gray"/>
      <geometry>
        <cylinder length="0.0222" radius="0.04"/>
      </geometry>
    </visual>
    <collision>
      <origin rpy="0 0 0" xyz="0 0 -0.0111"/>
      <material name="gray"/>
      <geometry>
        <cylinder length="0.0222" radius="0.04"/>
      </geometry>
    </collision>
  </link>
  <joint name="arm_left_ft_joint" type="fixed">
    <origin rpy="0 0 0" xyz="0 0 0.0222"/>
    <parent link="arm_left_link7"/>
    <child link="arm_left_ft_link"/>
  </joint>
  <!-- right gripper & eef link -->
  <link name="arm_right_gripper_link">
    <visual>
      <material name="gray"/>
      <origin rpy="0 0 0" xyz="0 0 0.0"/>
      <geometry>
        <mesh filename="package://horti_description/meshes/gripper/4Finger_visual.stl" scale="0.001 0.001 0.001"/>
      </geometry>
    </visual>
    <collision>
      <origin rpy="0 0 0" xyz="0 0 -0.04"/>
      <geometry>
        <mesh filename="package://horti_description/meshes/gripper/4Finger_collision.stl" scale="0.001 0.001 0.001"/>
      </geometry>
    </collision>
  </link>
  <joint name="arm_right_gripper_joint" type="fixed">
    <origin rpy="0 0 -0.7853981633974483" xyz="0 0 0"/>
    <parent link="arm_right_ft_link"/>
    <child link="arm_right_gripper_link"/>
  </joint>
  <link name="arm_right_eef_link"/>
  <joint name="arm_right_eef_joint" type="fixed">
    <origin rpy="0 0 0" xyz="0 0 0.08"/>
    <parent link="arm_right_gripper_link"/>
    <child link="arm_right_eef_link"/>
  </joint>
  <!-- left gripper & eef link -->
  <link name="arm_left_gripper_link">
    <visual>
      <material name="gray"/>
      <origin rpy="0 0 0" xyz="0 0 0.05"/>
      <geometry>
        <cylinder length="0.1" radius="0.03"/>
      </geometry>
    </visual>
    <collision>
      <origin rpy="0 0 0" xyz="0 0 0.05"/>
      <geometry>
        <cylinder length="0.1" radius="0.03"/>
      </geometry>
    </collision>
  </link>
  <joint name="arm_left_gripper_joint" type="fixed">
    <origin rpy="0 0 0" xyz="0 0 0"/>
    <parent link="arm_left_ft_link"/>
    <child link="arm_left_gripper_link"/>
  </joint>
  <link name="arm_left_eef_link"/>
  <joint name="arm_left_eef_joint" type="fixed">
    <origin rpy="0 0 0" xyz="0 0 0.1"/>
    <parent link="arm_left_gripper_link"/>
    <child link="arm_left_eef_link"/>
  </joint>
  <link name="head_mount_link">
    <visual>
      <material name="gray"/>
      <origin rpy="1.5707963267948966 0 0" xyz="0 0 -0.4"/>
      <geometry>
        <mesh filename="package://horti_description/meshes/lite6/visual/xarm6LiteHolder.STL"/>
      </geometry>
    </visual>
    <collision>
      <origin rpy="1.5707963267948966 0 0" xyz="0 0 -0.4"/>
      <geometry>
        <mesh filename="package://horti_description/meshes/lite6/visual/xarm6LiteHolder.STL"/>
      </geometry>
    </collision>
  </link>
  <joint name="head_mount_joint" type="fixed">
    <origin rpy="0 0 -1.5707963267948966" xyz="0 0.08 0.4"/>
    <parent link="arm_holder_link"/>
    <child link="head_mount_link"/>
  </joint>
  <joint name="head_world_joint" type="fixed">
    <parent link="head_mount_link"/>
    <child link="head_link_base"/>
    <origin rpy=" 0 0.7853981633974483 0" xyz="0.005656854249492381 0.0 -0.00565685424949238"/>
  </joint>
  <!-- collision_type values: visual, reduced_mesh_auto, reduced_mesh_manual_quality, reduced_mesh_manual_performance, spheres, shapes, capsules-->
  <material name="head_White">
    <color rgba="1.0 1.0 1.0 1.0"/>
  </material>
  <material name="head_Silver">
    <color rgba="0.753 0.753 0.753 1.0"/>
  </material>
  <link name="head_link_base">
    <inertial>
      <origin rpy="0 0 0" xyz="-0.00829544579053192 3.26357432323433E-05 0.0631194584987089"/>
      <mass value="2.11"/>
      <inertia ixx="0" ixy="0" ixz="0" iyy="0" iyz="0" izz="0"/>
    </inertial>
    <visual>
      <origin rpy="0 0 0" xyz="0 0 0"/>
      <geometry>
        <mesh filename="package://horti_description/meshes/lite6/visual/base.stl"/>
      </geometry>
      <material name="head_White"/>
    </visual>
    <collision>
      <geometry>
        <mesh filename="package://horti_description/meshes/lite6/visual/base.stl"/>
      </geometry>
    </collision>
  </link>
  <link name="head_link1">
    <inertial>
      <origin rpy="0 0 0" xyz="-0.00036 0.042 -0.0025"/>
      <mass value="1.411"/>
      <inertia ixx="1.45164E-03" ixy="1.24E-05" ixz="-6.7E-06" iyy="8.873E-04" iyz="1.255E-04" izz="1.31993E-03"/>
    </inertial>
    <visual>
      <origin rpy="0 0 0" xyz="0 0 0"/>
      <geometry>
        <mesh filename="package://horti_description/meshes/lite6/visual/link1.stl"/>
      </geometry>
      <material name="head_White"/>
    </visual>
    <collision>
      <geometry>
        <mesh filename="package://horti_description/meshes/lite6/visual/link1.stl"/>
      </geometry>
    </collision>
  </link>
  <joint name="head_joint1" type="revolute">
    <origin rpy="0 0 0" xyz="0 0 0.2433"/>
    <parent link="head_link_base"/>
    <child link="head_link1"/>
    <axis xyz="0 0 1"/>
    <limit effort="32.0" lower="-6.283185307179586" upper="6.283185307179586" velocity="3.14"/>
    <dynamics damping="1.0" friction="1.0"/>
  </joint>
  <link name="head_link2">
    <inertial>
      <origin rpy="0 0 0" xyz="0.179 0.0 0.0584"/>
      <mass value="1.34"/>
      <inertia ixx="1.5854E-03" ixy="-6.766E-06" ixz="-1.15136E-03" iyy="5.6097E-03" iyz="1.14E-06" izz="4.85E-03"/>
    </inertial>
    <visual>
      <origin rpy="0 0 0" xyz="0 0 0"/>
      <geometry>
        <mesh filename="package://horti_description/meshes/lite6/visual/link2.stl"/>
      </geometry>
      <material name="head_White"/>
    </visual>
    <collision>
      <geometry>
        <mesh filename="package://horti_description/meshes/lite6/visual/link2.stl"/>
      </geometry>
    </collision>
  </link>
  <joint name="head_joint2" type="revolute">
    <origin rpy="1.5708 -1.5708 3.1416" xyz="0 0 0"/>
    <parent link="head_link1"/>
    <child link="head_link2"/>
    <axis xyz="0 0 1"/>
    <limit effort="32.0" lower="-2.61799" upper="2.61799" velocity="3.14"/>
    <dynamics damping="1.0" friction="1.0"/>
  </joint>
  <link name="head_link3">
    <inertial>
      <origin rpy="0 0 0" xyz="0.072 -0.036 -0.001"/>
      <mass value="0.953"/>
      <inertia ixx="8.861E-04" ixy="-3.9287E-04" ixz="7.066E-05" iyy="1.5785E-03" iyz="-2.445E-05" izz="1.84677E-03"/>
    </inertial>
    <visual>
      <origin rpy="0 0 0" xyz="0 0 0"/>
      <geometry>
        <mesh filename="package://horti_description/meshes/lite6/visual/link3.stl"/>
      </geometry>
      <material name="head_White"/>
    </visual>
    <collision>
      <geometry>
        <mesh filename="package://horti_description/meshes/lite6/visual/link3.stl"/>
      </geometry>
    </collision>
  </link>
  <joint name="head_joint3" type="revolute">
    <origin rpy="-3.1416 0 1.5708" xyz="0.2 0 0"/>
    <parent link="head_link2"/>
    <child link="head_link3"/>
    <axis xyz="0 0 1"/>
    <limit effort="18.0" lower="-0.061087" upper="5.235988" velocity="3.14"/>
    <dynamics damping="1.0" friction="1.0"/>
  </joint>
  <link name="head_link4">
    <inertial>
      <origin rpy="0 0 0" xyz="-0.002 -0.0285 -0.0813"/>
      <mass value="1.284"/>
      <inertia ixx="3.705E-03" ixy="-2.0E-06" ixz="7.17E-06" iyy="3.0455E-03" iyz="-9.3188E-04" izz="1.5413E-03"/>
    </inertial>
    <visual>
      <origin rpy="0 0 0" xyz="0 0 0"/>
      <geometry>
        <mesh filename="package://horti_description/meshes/lite6/visual/link4.stl"/>
      </geometry>
      <material name="head_White"/>
    </visual>
    <collision>
      <geometry>
        <mesh filename="package://horti_description/meshes/lite6/visual/link4.stl"/>
      </geometry>
    </collision>
  </link>
  <joint name="head_joint4" type="revolute">
    <origin rpy="1.5708 0 0" xyz="0.087 -0.2276 0"/>
    <parent link="head_link3"/>
    <child link="head_link4"/>
    <axis xyz="0 0 1"/>
    <limit effort="2.5" lower="-6.283185307179586" upper="6.283185307179586" velocity="3.14"/>
    <dynamics damping="0.1" friction="0.1"/>
  </joint>
  <link name="head_link5">
    <inertial>
      <origin rpy="0 0 0" xyz="0.0 0.010 0.0019"/>
      <mass value="0.804"/>
      <inertia ixx="5.668E-04" ixy="6E-07" ixz="-5.3E-06" iyy="5.077E-04" iyz="-4.8E-07" izz="5.3E-04"/>
    </inertial>
    <visual>
      <origin rpy="0 0 0" xyz="0 0 0"/>
      <geometry>
        <mesh filename="package://horti_description/meshes/lite6/visual/link5.stl"/>
      </geometry>
      <material name="head_Silver"/>
    </visual>
    <collision>
      <geometry>
        <mesh filename="package://horti_description/meshes/lite6/visual/link5.stl"/>
      </geometry>
    </collision>
  </link>
  <joint name="head_joint5" type="revolute">
    <origin rpy="1.5708 0 0" xyz="0 0 0"/>
    <parent link="head_link4"/>
    <child link="head_link5"/>
    <axis xyz="0 0 1"/>
    <limit effort="2.5" lower="-2.1642" upper="2.1642" velocity="3.14"/>
    <dynamics damping="0.1" friction="0.1"/>
  </joint>
  <link name="head_link6">
    <inertial>
      <origin rpy="0 0 0" xyz="0.0 -0.00194 -0.0102"/>
      <mass value="0.180"/>
      <inertia ixx="7.726E-05" ixy="1E-06" ixz="4E-07" iyy="8.5665E-05" iyz="-6E-07" izz="1.4814E-04"/>
    </inertial>
    <visual>
      <origin rpy="0 0 0" xyz="0 0 0"/>
      <geometry>
        <mesh filename="package://horti_description/meshes/lite6/visual/link6.stl"/>
      </geometry>
      <material name="head_Silver"/>
    </visual>
    <collision>
      <geometry>
        <mesh filename="package://horti_description/meshes/lite6/visual/link6.stl"/>
      </geometry>
    </collision>
  </link>
  <joint name="head_joint6" type="revolute">
    <origin rpy="-1.5708 0 0" xyz="0 0.0615 0"/>
    <parent link="head_link5"/>
    <child link="head_link6"/>
    <axis xyz="0 0 1"/>
    <limit effort="2.5" lower="-6.283185307179586" upper="6.283185307179586" velocity="3.14"/>
    <dynamics damping="0.1" friction="0.1"/>
  </joint>
  <link name="head_link_eef"/>
  <joint name="head_joint_eef" type="fixed">
    <origin rpy="0 0 0" xyz="0 0 0"/>
    <parent link="head_link6"/>
    <child link="head_link_eef"/>
  </joint>
  <transmission name="head_tran1">
    <type>transmission_interface/SimpleTransmission</type>
    <joint name="head_joint1">
      <hardwareInterface>hardware_interface/PositionJointInterface</hardwareInterface>
    </joint>
    <actuator name="head_motor1">
      <hardwareInterface>hardware_interface/PositionJointInterface</hardwareInterface>
      <mechanicalReduction>100</mechanicalReduction>
    </actuator>
  </transmission>
  <transmission name="head_tran2">
    <type>transmission_interface/SimpleTransmission</type>
    <joint name="head_joint2">
      <hardwareInterface>hardware_interface/PositionJointInterface</hardwareInterface>
    </joint>
    <actuator name="head_motor2">
      <hardwareInterface>hardware_interface/PositionJointInterface</hardwareInterface>
      <mechanicalReduction>100</mechanicalReduction>
    </actuator>
  </transmission>
  <transmission name="head_tran3">
    <type>transmission_interface/SimpleTransmission</type>
    <joint name="head_joint3">
      <hardwareInterface>hardware_interface/PositionJointInterface</hardwareInterface>
    </joint>
    <actuator name="head_motor3">
      <hardwareInterface>hardware_interface/PositionJointInterface</hardwareInterface>
      <mechanicalReduction>100</mechanicalReduction>
    </actuator>
  </transmission>
  <transmission name="head_tran4">
    <type>transmission_interface/SimpleTransmission</type>
    <joint name="head_joint4">
      <hardwareInterface>hardware_interface/PositionJointInterface</hardwareInterface>
    </joint>
    <actuator name="head_motor3">
      <hardwareInterface>hardware_interface/PositionJointInterface</hardwareInterface>
      <mechanicalReduction>100</mechanicalReduction>
    </actuator>
  </transmission>
  <transmission name="head_tran5">
    <type>transmission_interface/SimpleTransmission</type>
    <joint name="head_joint5">
      <hardwareInterface>hardware_interface/PositionJointInterface</hardwareInterface>
    </joint>
    <actuator name="head_motor5">
      <hardwareInterface>hardware_interface/PositionJointInterface</hardwareInterface>
      <mechanicalReduction>100</mechanicalReduction>
    </actuator>
  </transmission>
  <transmission name="head_tran6">
    <type>transmission_interface/SimpleTransmission</type>
    <joint name="head_joint6">
      <hardwareInterface>hardware_interface/PositionJointInterface</hardwareInterface>
    </joint>
    <actuator name="head_motor6">
      <hardwareInterface>hardware_interface/PositionJointInterface</hardwareInterface>
      <mechanicalReduction>100</mechanicalReduction>
    </actuator>
  </transmission>
  <gazebo reference="head_link_base">
    <selfCollide>true</selfCollide>
  </gazebo>
  <gazebo reference="head_link1">
    <selfCollide>true</selfCollide>
  </gazebo>
  <gazebo reference="head_link2">
    <selfCollide>true</selfCollide>
  </gazebo>
  <gazebo reference="head_link3">
    <selfCollide>true</selfCollide>
  </gazebo>
  <gazebo reference="head_link4">
    <selfCollide>true</selfCollide>
  </gazebo>
  <gazebo reference="head_link5">
    <selfCollide>true</selfCollide>
  </gazebo>
  <gazebo reference="head_link6">
    <selfCollide>true</selfCollide>
  </gazebo>
  <link name="zed2i_holder_link">
    <visual>
      <material name="gray"/>
      <origin rpy="0 0 0" xyz="0 0 0"/>
      <geometry>
        <mesh filename="package://horti_description/meshes/camera/ZED2i_adaptor.STL"/>
      </geometry>
    </visual>
    <!-- we dont need a low quality mesh for this piece -->
    <collision>
      <geometry>
        <mesh filename="package://horti_description/meshes/camera/ZED2i_adaptor.STL"/>
      </geometry>
    </collision>
  </link>
  <joint name="zed2i_holder_joint" type="fixed">
    <origin rpy="0 0 0.7853981633974483" xyz="0 0 0"/>
    <parent link="head_link_eef"/>
    <child link="zed2i_holder_link"/>
  </joint>
  <!-- Camera mounting point (the threaded screw hole in the bottom) -->
  <link name="zed2i_base_link"/>
  <joint name="zed2i_base_joint" type="fixed">
    <parent link="zed2i_holder_link"/>
    <child link="zed2i_base_link"/>
    <origin rpy="3.141592653589793 -1.5707963267948966 0.0" xyz="-0.015 0 0.054"/>
  </joint>
  <!-- Camera Center -->
  <link name="zed2i_camera_center">
    <visual>
      <origin rpy="0 0 0" xyz="-0.01 0 0"/>
      <geometry>
        <mesh filename="package://horti_description/meshes/zed/zed2i.stl"/>
      </geometry>
      <material name="zed2i_mat"/>
    </visual>
    <!-- <collision>
        <geometry>
          <mesh filename="package://horti_description/meshes/zed/${model}.stl" scale="0.8 0.8 0.8"/>
        </geometry>
      </collision> -->
  </link>
  <joint name="zed2i_camera_center_joint" type="fixed">
    <parent link="zed2i_base_link"/>
    <child link="zed2i_camera_center"/>
    <origin rpy="0 0.0 0" xyz="0 0 0.015"/>
  </joint>
  <!-- Left Camera -->
  <link name="zed2i_left_camera_frame"/>
  <joint name="zed2i_left_camera_joint" type="fixed">
    <parent link="zed2i_camera_center"/>
    <child link="zed2i_left_camera_frame"/>
    <origin rpy="0 0 0" xyz="0 0.06 0"/>
  </joint>
  <link name="zed2i_left_camera_optical_frame"/>
  <joint name="zed2i_left_camera_optical_joint" type="fixed">
    <origin rpy="-1.5707963267948966 0.0 -1.5707963267948966" xyz="-0.01 0 0"/>
    <parent link="zed2i_left_camera_frame"/>
    <child link="zed2i_left_camera_optical_frame"/>
  </joint>
  <!-- Right Camera -->
  <link name="zed2i_right_camera_frame"/>
  <joint name="zed2i_right_camera_joint" type="fixed">
    <parent link="zed2i_camera_center"/>
    <child link="zed2i_right_camera_frame"/>
    <origin rpy="0 0 0" xyz="0 -0.06 0"/>
  </joint>
  <link name="zed2i_right_camera_optical_frame"/>
  <joint name="zed2i_right_camera_optical_joint" type="fixed">
    <origin rpy="-1.5707963267948966 0.0 -1.5707963267948966" xyz="-0.01 0 0"/>
    <parent link="zed2i_right_camera_frame"/>
    <child link="zed2i_right_camera_optical_frame"/>
  </joint>
  <link name="zed2i_mag_link"/>
  <joint name="zed2i_mag_joint" type="fixed">
    <parent link="zed2i_camera_center"/>
    <child link="zed2i_mag_link"/>
    <origin rpy="0 0 0" xyz="0 0 0"/>
  </joint>
  <link name="zed2i_baro_link"/>
  <joint name="zed2i_baro_joint" type="fixed">
    <parent link="zed2i_camera_center"/>
    <child link="zed2i_baro_link"/>
    <origin rpy="0 0 0" xyz="0 0 0"/>
  </joint>
  <link name="zed2i_temp_left_link"/>
  <joint name="zed2i_temp_left_joint" type="fixed">
    <parent link="zed2i_left_camera_frame"/>
    <child link="zed2i_temp_left_link"/>
    <origin rpy="0 0 0" xyz="0 0 0"/>
  </joint>
  <link name="zed2i_temp_right_link"/>
  <joint name="zed2i_temp_right_joint" type="fixed">
    <parent link="zed2i_right_camera_frame"/>
    <child link="zed2i_temp_right_link"/>
    <origin rpy="0 0 0" xyz="0 0 0"/>
  </joint>
  <link name="zed2i_link">
    <visual>
      <material name="gray"/>
      <origin rpy="0 0 0" xyz="0 0 0"/>
      <geometry>
        <mesh filename="package://horti_description/meshes/camera/zed2i.stl"/>
      </geometry>
    </visual>
    <collision>
      <geometry>
        <mesh filename="package://horti_description/meshes/camera/zed2i.stl"/>
      </geometry>
    </collision>
  </link>
  <joint name="zed2i_joint" type="fixed">
    <origin rpy="3.141592653589793 -1.5707963267948966 0" xyz="0 0 0.044"/>
    <parent link="zed2i_holder_link"/>
    <child link="zed2i_link"/>
  </joint>
  <!-- Left/Depth camera -->
  <gazebo reference="zed2i_left_camera_frame">
    <!-- Raw images (with lens distortion) -->
    <sensor name="zed2i_left_raw_camera" type="camera">
      <always_on>true</always_on>
      <update_rate>15.0</update_rate>
      <visualize>false</visualize>
      <camera name="zed2i_left_raw">
        <horizontal_fov>1.7633</horizontal_fov>
        <image>
          <width>1280</width>
          <height>720</height>
          <format>B8G8R8</format>
        </image>
        <clip>
          <near>0.02</near>
          <far>3.0</far>
        </clip>
        <noise>
          <type>gaussian</type>
          <mean>0.0</mean>
          <stddev>0.007</stddev>
        </noise>
        <distortion>
          <!-- Values copied from an actual zed2i camera -->
          <k1>-0.043693598</k1>
          <k2>0.0146164996</k2>
          <p1>-0.006573319</p1>
          <p2>-0.000216900</p2>
          <k3>0.000084328</k3>
          <center>0.5 0.5</center>
        </distortion>
      </camera>
      <plugin filename="libgazebo_ros_camera.so" name="camera_controller">
        <robotNamespace>/</robotNamespace>
        <cameraName>zed2i/left_raw</cameraName>
        <imageTopicName>image_raw_color</imageTopicName>
        <cameraInfoTopicName>camera_info</cameraInfoTopicName>
        <frameName>zed2i_left_camera_optical_frame</frameName>
        <distortionK1>-0.043693598</distortionK1>
        <distortionK2>0.0146164996</distortionK2>
        <distortionT1>-0.006573319</distortionT1>
        <distortionT2>-0.000216900</distortionT2>
        <distortionK3>0.000084328</distortionK3>
        <CxPrime>648.5</CxPrime>
        <Cx>648.5</Cx>
        <Cy>366.8340148925781</Cy>
        <hackBaseline>0.0</hackBaseline>
      </plugin>
    </sensor>
    <sensor name="zed2i_left_camera" type="depth">
      <!-- Rectified images, Depth images, Point Clouds -->
      <always_on>true</always_on>
      <update_rate>15.0</update_rate>
      <visualize>false</visualize>
      <camera name="zed2i_left">
        <horizontal_fov>1.7633</horizontal_fov>
        <image>
          <width>1280</width>
          <height>720</height>
          <format>B8G8R8</format>
        </image>
        <clip>
          <near>0.02</near>
          <far>300</far>
        </clip>
        <noise>
          <type>gaussian</type>
          <mean>0.0</mean>
          <stddev>0.007</stddev>
        </noise>
      </camera>
      <plugin filename="libgazebo_ros_openni_kinect.so" name="camera_controller">
        <robotNamespace>/</robotNamespace>
        <cameraName>zed2i</cameraName>
        <imageTopicName>left/image_rect_color</imageTopicName>
        <cameraInfoTopicName>left/camera_info</cameraInfoTopicName>
        <depthImageTopicName>depth/depth_registered</depthImageTopicName>
        <depthImageInfoTopicName>depth/camera_info</depthImageInfoTopicName>
        <pointCloudTopicName>point_cloud/cloud_registered</pointCloudTopicName>
        <pointCloudCutoff>0.3</pointCloudCutoff>
        <pointCloudCutoffMax>20.0</pointCloudCutoffMax>
        <frameName>zed2i_left_camera_optical_frame</frameName>
        <baseline>0.12</baseline>
        <CxPrime>658.8206787109375</CxPrime>
        <Cx>658.8206787109375</Cx>
        <Cy>372.25787353515625</Cy>
        <hackBaseline>0.0</hackBaseline>
      </plugin>
    </sensor>
  </gazebo>
  <!-- Right camera -->
  <gazebo reference="zed2i_right_camera_frame">
    <!-- Raw images (with lens distortion) -->
    <sensor name="zed2i_right_raw_camera" type="camera">
      <always_on>true</always_on>
      <update_rate>15.0</update_rate>
      <visualize>false</visualize>
      <camera name="zed2i_right_raw">
        <horizontal_fov>1.7633</horizontal_fov>
        <image>
          <width>1280</width>
          <height>720</height>
          <format>B8G8R8</format>
        </image>
        <clip>
          <near>0.02</near>
          <far>300</far>
        </clip>
        <noise>
          <type>gaussian</type>
          <mean>0.0</mean>
          <stddev>0.007</stddev>
        </noise>
        <distortion>
          <k1>-0.040993299</k1>
          <k2>0.009593590</k2>
          <p1>-0.0044298zed2i_gazebo49</p1>
          <p2>0.000192024</p2>
          <k3>-0.000320880</k3>
          <center>0.5 0.5</center>
        </distortion>
      </camera>
      <plugin filename="libgazebo_ros_camera.so" name="camera_controller">
        <robotNamespace>/</robotNamespace>
        <cameraName>zed2i/right_raw</cameraName>
        <imageTopicName>image_raw_color</imageTopicName>
        <cameraInfoTopicName>camera_info</cameraInfoTopicName>
        <frameName>zed2i_right_camera_optical_frame</frameName>
        <distortionK1>-0.040993299</distortionK1>
        <distortionK2>0.009593590</distortionK2>
        <distortionT1>-0.004429849</distortionT1>
        <distortionT2>0.000192024</distortionT2>
        <distortionK3>-0.000320880</distortionK3>
        <CxPrime>659.3049926757812</CxPrime>
        <Cx>659.3049926757812</Cx>
        <Cy>371.39849853515625</Cy>
        <hackBaseline>0.12</hackBaseline>
      </plugin>
    </sensor>
    <sensor name="zed2i_right_camera" type="camera">
      <!-- Rectified images -->
      <always_on>true</always_on>
      <update_rate>15.0</update_rate>
      <visualize>false</visualize>
      <camera name="zed2i_right">
        <horizontal_fov>1.7633</horizontal_fov>
        <image>
          <width>1280</width>
          <height>720</height>
          <format>B8G8R8</format>
        </image>
        <clip>
          <near>0.02</near>
          <far>300</far>
        </clip>
        <noise>
          <type>gaussian</type>
          <mean>0.0</mean>
          <stddev>0.007</stddev>
        </noise>
      </camera>
      <plugin filename="libgazebo_ros_camera.so" name="camera_controller">
        <robotNamespace>/</robotNamespace>
        <cameraName>zed2i/right</cameraName>
        <imageTopicName>image_rect_color</imageTopicName>
        <cameraInfoTopicName>camera_info</cameraInfoTopicName>
        <frameName>zed2i_right_camera_optical_frame</frameName>
        <CxPrime>658.8206787109375</CxPrime>
        <Cx>658.8206787109375</Cx>
        <Cy>372.25787353515625</Cy>
        <hackBaseline>0.12</hackBaseline>
      </plugin>
    </sensor>
  </gazebo>
  <!-- IMU -->
  <gazebo reference="zed2i_left_camera_frame">
    <sensor name="zed2i_imu_sensor" type="imu">
      <update_rate>100</update_rate>
      <plugin filename="libgazebo_ros_imu_sensor.so" name="imu_plugin">
        <robotNamespace>/</robotNamespace>
        <topicName>zed2i/imu/data</topicName>
        <frameName>zed2i_imu_link</frameName>
        <updateRateHZ>100.0</updateRateHZ>
        <gaussianNoise>0.01</gaussianNoise>
        <initialOrientationAsReference>false</initialOrientationAsReference>
        <!-- IMU frame offset copied from an actual zed2i camera -->
        <xyzOffset>-0.002 -0.023 -0.002</xyzOffset>
        <rpyOffset>0.0014025 -0.0000012 -0.0016915</rpyOffset>
      </plugin>
    </sensor>
  </gazebo>
</robot>

