<?xml version="1.0" ?>
<!-- =================================================================================== -->
<!-- |    This document was autogenerated by xacro from /veriler/salih/Desktop/master_thesis/catkin_ws/src/mick_model/mick_description/urdf/mick_robot.urdf.xacro | -->
<!-- |    EDITING THIS FILE BY HAND IS NOT RECOMMENDED                                 | -->
<!-- =================================================================================== -->
<robot name="mick">
  <!-- ground instead of world, for the arms to attach -->
  <link name="ground"/>
  <material name="gray">
    <color rgba="0.4 0.4 0.4 1"/>
  </material>
  <material name="Black">
    <color rgba="0.0 0.0 0.0 1.0"/>
  </material>
  <material name="Red">
    <color rgba="0.8 0.0 0.0 1.0"/>
  </material>
  <material name="White">
    <color rgba="1.0 1.0 1.0 1.0"/>
  </material>
  <material name="Silver">
    <color rgba="0.753 0.753 0.753 1.0"/>
  </material>
  <joint name="head_world_joint" type="fixed">
    <parent link="ground"/>
    <child link="head_link_base"/>
    <origin rpy="0 0 0" xyz="0 0 0"/>
  </joint>
  <!-- collision_type values: visual, reduced_mesh_auto, reduced_mesh_manual_quality, reduced_mesh_manual_performance, spheres, shapes, capsules-->
  <material name="head_White">
    <color rgba="1.0 1.0 1.0 1.0"/>
  </material>
  <material name="head_Silver">
    <color rgba="0.753 0.753 0.753 1.0"/>
  </material>
  <link name="head_link_base">
    <inertial>
      <origin rpy="0 0 0" xyz="-0.00829544579053192 3.26357432323433E-05 0.0631194584987089"/>
      <mass value="2.11"/>
      <inertia ixx="0" ixy="0" ixz="0" iyy="0" iyz="0" izz="0"/>
    </inertial>
    <visual>
      <origin rpy="0 0 0" xyz="0 0 0"/>
      <geometry>
        <mesh filename="package://mick_description/meshes/lite6/visual/base.stl"/>
      </geometry>
      <material name="head_White"/>
    </visual>
    <collision>
      <geometry>
        <mesh filename="package://mick_description/meshes/lite6/visual/base.stl"/>
      </geometry>
    </collision>
  </link>
  <link name="head_link1">
    <inertial>
      <origin rpy="0 0 0" xyz="-0.00036 0.042 -0.0025"/>
      <mass value="1.411"/>
      <inertia ixx="1.45164E-03" ixy="1.24E-05" ixz="-6.7E-06" iyy="8.873E-04" iyz="1.255E-04" izz="1.31993E-03"/>
    </inertial>
    <visual>
      <origin rpy="0 0 0" xyz="0 0 0"/>
      <geometry>
        <mesh filename="package://mick_description/meshes/lite6/visual/link1.stl"/>
      </geometry>
      <material name="head_White"/>
    </visual>
    <collision>
      <geometry>
        <mesh filename="package://mick_description/meshes/lite6/visual/link1.stl"/>
      </geometry>
    </collision>
  </link>
  <joint name="head_joint1" type="revolute">
    <origin rpy="0 0 0" xyz="0 0 0.2433"/>
    <parent link="head_link_base"/>
    <child link="head_link1"/>
    <axis xyz="0 0 1"/>
    <limit effort="32.0" lower="-6.283185307179586" upper="6.283185307179586" velocity="3.14"/>
    <dynamics damping="1.0" friction="1.0"/>
  </joint>
  <link name="head_link2">
    <inertial>
      <origin rpy="0 0 0" xyz="0.179 0.0 0.0584"/>
      <mass value="1.34"/>
      <inertia ixx="1.5854E-03" ixy="-6.766E-06" ixz="-1.15136E-03" iyy="5.6097E-03" iyz="1.14E-06" izz="4.85E-03"/>
    </inertial>
    <visual>
      <origin rpy="0 0 0" xyz="0 0 0"/>
      <geometry>
        <mesh filename="package://mick_description/meshes/lite6/visual/link2.stl"/>
      </geometry>
      <material name="head_White"/>
    </visual>
    <collision>
      <geometry>
        <mesh filename="package://mick_description/meshes/lite6/visual/link2.stl"/>
      </geometry>
    </collision>
  </link>
  <joint name="head_joint2" type="revolute">
    <origin rpy="1.5708 -1.5708 3.1416" xyz="0 0 0"/>
    <parent link="head_link1"/>
    <child link="head_link2"/>
    <axis xyz="0 0 1"/>
    <limit effort="32.0" lower="-2.61799" upper="2.61799" velocity="3.14"/>
    <dynamics damping="1.0" friction="1.0"/>
  </joint>
  <link name="head_link3">
    <inertial>
      <origin rpy="0 0 0" xyz="0.072 -0.036 -0.001"/>
      <mass value="0.953"/>
      <inertia ixx="8.861E-04" ixy="-3.9287E-04" ixz="7.066E-05" iyy="1.5785E-03" iyz="-2.445E-05" izz="1.84677E-03"/>
    </inertial>
    <visual>
      <origin rpy="0 0 0" xyz="0 0 0"/>
      <geometry>
        <mesh filename="package://mick_description/meshes/lite6/visual/link3.stl"/>
      </geometry>
      <material name="head_White"/>
    </visual>
    <collision>
      <geometry>
        <mesh filename="package://mick_description/meshes/lite6/visual/link3.stl"/>
      </geometry>
    </collision>
  </link>
  <joint name="head_joint3" type="revolute">
    <origin rpy="-3.1416 0 1.5708" xyz="0.2 0 0"/>
    <parent link="head_link2"/>
    <child link="head_link3"/>
    <axis xyz="0 0 1"/>
    <limit effort="18.0" lower="-0.061087" upper="5.235988" velocity="3.14"/>
    <dynamics damping="1.0" friction="1.0"/>
  </joint>
  <link name="head_link4">
    <inertial>
      <origin rpy="0 0 0" xyz="-0.002 -0.0285 -0.0813"/>
      <mass value="1.284"/>
      <inertia ixx="3.705E-03" ixy="-2.0E-06" ixz="7.17E-06" iyy="3.0455E-03" iyz="-9.3188E-04" izz="1.5413E-03"/>
    </inertial>
    <visual>
      <origin rpy="0 0 0" xyz="0 0 0"/>
      <geometry>
        <mesh filename="package://mick_description/meshes/lite6/visual/link4.stl"/>
      </geometry>
      <material name="head_White"/>
    </visual>
    <collision>
      <geometry>
        <mesh filename="package://mick_description/meshes/lite6/visual/link4.stl"/>
      </geometry>
    </collision>
  </link>
  <joint name="head_joint4" type="revolute">
    <origin rpy="1.5708 0 0" xyz="0.087 -0.2276 0"/>
    <parent link="head_link3"/>
    <child link="head_link4"/>
    <axis xyz="0 0 1"/>
    <limit effort="2.5" lower="-6.283185307179586" upper="6.283185307179586" velocity="3.14"/>
    <dynamics damping="0.1" friction="0.1"/>
  </joint>
  <link name="head_link5">
    <inertial>
      <origin rpy="0 0 0" xyz="0.0 0.010 0.0019"/>
      <mass value="0.804"/>
      <inertia ixx="5.668E-04" ixy="6E-07" ixz="-5.3E-06" iyy="5.077E-04" iyz="-4.8E-07" izz="5.3E-04"/>
    </inertial>
    <visual>
      <origin rpy="0 0 0" xyz="0 0 0"/>
      <geometry>
        <mesh filename="package://mick_description/meshes/lite6/visual/link5.stl"/>
      </geometry>
      <material name="head_Silver"/>
    </visual>
    <collision>
      <geometry>
        <mesh filename="package://mick_description/meshes/lite6/visual/link5.stl"/>
      </geometry>
    </collision>
  </link>
  <joint name="head_joint5" type="revolute">
    <origin rpy="1.5708 0 0" xyz="0 0 0"/>
    <parent link="head_link4"/>
    <child link="head_link5"/>
    <axis xyz="0 0 1"/>
    <limit effort="2.5" lower="-2.1642" upper="2.1642" velocity="3.14"/>
    <dynamics damping="0.1" friction="0.1"/>
  </joint>
  <link name="head_link6">
    <inertial>
      <origin rpy="0 0 0" xyz="0.0 -0.00194 -0.0102"/>
      <mass value="0.180"/>
      <inertia ixx="7.726E-05" ixy="1E-06" ixz="4E-07" iyy="8.5665E-05" iyz="-6E-07" izz="1.4814E-04"/>
    </inertial>
    <visual>
      <origin rpy="0 0 0" xyz="0 0 0"/>
      <geometry>
        <mesh filename="package://mick_description/meshes/lite6/visual/link6.stl"/>
      </geometry>
      <material name="head_Silver"/>
    </visual>
    <collision>
      <geometry>
        <mesh filename="package://mick_description/meshes/lite6/visual/link6.stl"/>
      </geometry>
    </collision>
  </link>
  <joint name="head_joint6" type="revolute">
    <origin rpy="-1.5708 0 0" xyz="0 0.0615 0"/>
    <parent link="head_link5"/>
    <child link="head_link6"/>
    <axis xyz="0 0 1"/>
    <limit effort="2.5" lower="-6.283185307179586" upper="6.283185307179586" velocity="3.14"/>
    <dynamics damping="0.1" friction="0.1"/>
  </joint>
  <link name="head_link_eef"/>
  <joint name="head_joint_eef" type="fixed">
    <origin rpy="0 0 0" xyz="0 0 0"/>
    <parent link="head_link6"/>
    <child link="head_link_eef"/>
  </joint>
  <transmission name="head_tran1">
    <type>transmission_interface/SimpleTransmission</type>
    <joint name="head_joint1">
      <hardwareInterface>hardware_interface/PositionJointInterface</hardwareInterface>
    </joint>
    <actuator name="head_motor1">
      <hardwareInterface>hardware_interface/PositionJointInterface</hardwareInterface>
      <mechanicalReduction>100</mechanicalReduction>
    </actuator>
  </transmission>
  <transmission name="head_tran2">
    <type>transmission_interface/SimpleTransmission</type>
    <joint name="head_joint2">
      <hardwareInterface>hardware_interface/PositionJointInterface</hardwareInterface>
    </joint>
    <actuator name="head_motor2">
      <hardwareInterface>hardware_interface/PositionJointInterface</hardwareInterface>
      <mechanicalReduction>100</mechanicalReduction>
    </actuator>
  </transmission>
  <transmission name="head_tran3">
    <type>transmission_interface/SimpleTransmission</type>
    <joint name="head_joint3">
      <hardwareInterface>hardware_interface/PositionJointInterface</hardwareInterface>
    </joint>
    <actuator name="head_motor3">
      <hardwareInterface>hardware_interface/PositionJointInterface</hardwareInterface>
      <mechanicalReduction>100</mechanicalReduction>
    </actuator>
  </transmission>
  <transmission name="head_tran4">
    <type>transmission_interface/SimpleTransmission</type>
    <joint name="head_joint4">
      <hardwareInterface>hardware_interface/PositionJointInterface</hardwareInterface>
    </joint>
    <actuator name="head_motor3">
      <hardwareInterface>hardware_interface/PositionJointInterface</hardwareInterface>
      <mechanicalReduction>100</mechanicalReduction>
    </actuator>
  </transmission>
  <transmission name="head_tran5">
    <type>transmission_interface/SimpleTransmission</type>
    <joint name="head_joint5">
      <hardwareInterface>hardware_interface/PositionJointInterface</hardwareInterface>
    </joint>
    <actuator name="head_motor5">
      <hardwareInterface>hardware_interface/PositionJointInterface</hardwareInterface>
      <mechanicalReduction>100</mechanicalReduction>
    </actuator>
  </transmission>
  <transmission name="head_tran6">
    <type>transmission_interface/SimpleTransmission</type>
    <joint name="head_joint6">
      <hardwareInterface>hardware_interface/PositionJointInterface</hardwareInterface>
    </joint>
    <actuator name="head_motor6">
      <hardwareInterface>hardware_interface/PositionJointInterface</hardwareInterface>
      <mechanicalReduction>100</mechanicalReduction>
    </actuator>
  </transmission>
  <gazebo reference="head_link_base">
    <selfCollide>true</selfCollide>
  </gazebo>
  <gazebo reference="head_link1">
    <selfCollide>true</selfCollide>
  </gazebo>
  <gazebo reference="head_link2">
    <selfCollide>true</selfCollide>
  </gazebo>
  <gazebo reference="head_link3">
    <selfCollide>true</selfCollide>
  </gazebo>
  <gazebo reference="head_link4">
    <selfCollide>true</selfCollide>
  </gazebo>
  <gazebo reference="head_link5">
    <selfCollide>true</selfCollide>
  </gazebo>
  <gazebo reference="head_link6">
    <selfCollide>true</selfCollide>
  </gazebo>
  <!--
  Author: Jimy Zhang <jimy.zhang@ufactory.cc> <jimy92@163.com>
  Contributers:
-->
  <joint name="other_world_joint" type="fixed">
    <parent link="ground"/>
    <child link="other_link_base"/>
    <origin rpy="0 0 3.141592654" xyz="0.5 0 0"/>
  </joint>
  <!-- collision_type values: visual, reduced_mesh_auto, reduced_mesh_manual_quality, reduced_mesh_manual_performance, spheres, shapes, capsules-->
  <link name="other_link_base">
    <inertial>
      <origin rpy="0 0 0" xyz="-0.021131 -0.0016302 0.056488"/>
      <mass value="2.612"/>
      <inertia ixx="0.0030595" ixy="0.00012259" ixz="-0.00062705" iyy="0.0037783" iyz="0.00027023" izz="0.0020125"/>
    </inertial>
    <visual>
      <origin rpy="0 0 0" xyz="0 0 0"/>
      <geometry>
        <mesh filename="package://mick_description/meshes/xarm7/visual/link_base.STL"/>
      </geometry>
      <material name="White"/>
    </visual>
    <collision>
      <geometry>
        <mesh filename="package://mick_description/meshes/xarm7/visual/link_base.STL"/>
      </geometry>
    </collision>
  </link>
  <link name="other_link1">
    <inertial>
      <origin rpy="0 0 0" xyz="0.00013 0.0301 -0.012"/>
      <mass value="2.459"/>
      <inertia ixx="0.005795" ixy="-1.078E-05" ixz="-2.63E-05" iyy="0.004969" iyz="0.000911" izz="0.003428"/>
    </inertial>
    <visual>
      <origin rpy="0 0 0" xyz="0 0 0"/>
      <geometry>
        <mesh filename="package://mick_description/meshes/xarm7/visual/link1.STL"/>
      </geometry>
      <material name="White"/>
    </visual>
    <collision>
      <geometry>
        <mesh filename="package://mick_description/meshes/xarm7/visual/link1.STL"/>
      </geometry>
    </collision>
  </link>
  <joint name="other_joint1" type="revolute">
    <origin rpy="0 0 0" xyz="0 0 0.267"/>
    <parent link="other_link_base"/>
    <child link="other_link1"/>
    <axis xyz="0 0 1"/>
    <limit effort="50" lower="-6.283185307179586" upper="6.283185307179586" velocity="3.14"/>
    <dynamics damping="10" friction="1"/>
  </joint>
  <link name="other_link2">
    <inertial>
      <origin rpy="0 0 0" xyz="0.0002 -0.12964 0.01692"/>
      <mass value="1.916"/>
      <inertia ixx="0.0097184" ixy="1.0E-06" ixz="-4.83E-06" iyy="0.0038705" iyz="0.0032" izz="0.007672"/>
    </inertial>
    <visual>
      <origin rpy="0 0 0" xyz="0 0 0"/>
      <geometry>
        <mesh filename="package://mick_description/meshes/xarm7/visual/link2.STL"/>
      </geometry>
      <material name="White"/>
    </visual>
    <collision>
      <geometry>
        <mesh filename="package://mick_description/meshes/xarm7/visual/link2.STL"/>
      </geometry>
    </collision>
  </link>
  <joint name="other_joint2" type="revolute">
    <origin rpy="-1.5708 0 0" xyz="0 0 0"/>
    <parent link="other_link1"/>
    <child link="other_link2"/>
    <axis xyz="0 0 1"/>
    <limit effort="50" lower="-2.059" upper="2.0944" velocity="3.14"/>
    <dynamics damping="10" friction="1"/>
  </joint>
  <link name="other_link3">
    <inertial>
      <origin rpy="0 0 0" xyz="0.04676 -0.02526 -0.00746"/>
      <mass value="1.6854"/>
      <inertia ixx="0.0031588" ixy="-3.1443E-04" ixz="5.8658E-04" iyy="0.002682" iyz="-3.469E-04" izz="0.0027105"/>
    </inertial>
    <visual>
      <origin rpy="0 0 0" xyz="0 0 0"/>
      <geometry>
        <mesh filename="package://mick_description/meshes/xarm7/visual/link3.STL"/>
      </geometry>
      <material name="White"/>
    </visual>
    <collision>
      <geometry>
        <mesh filename="package://mick_description/meshes/xarm7/visual/link3.STL"/>
      </geometry>
    </collision>
  </link>
  <joint name="other_joint3" type="revolute">
    <origin rpy="1.5708 0 0" xyz="0 -0.293 0"/>
    <parent link="other_link2"/>
    <child link="other_link3"/>
    <axis xyz="0 0 1"/>
    <limit effort="30" lower="-6.283185307179586" upper="6.283185307179586" velocity="3.14"/>
    <dynamics damping="5" friction="1"/>
  </joint>
  <link name="other_link4">
    <inertial>
      <origin rpy="0 0 0" xyz="0.07066 -0.11664 0.0117"/>
      <mass value="1.774"/>
      <inertia ixx="0.005967" ixy="-0.001382" ixz="-0.00088544" iyy="0.00363897" iyz="0.0017806" izz="0.005509226"/>
    </inertial>
    <visual>
      <origin rpy="0 0 0" xyz="0 0 0"/>
      <geometry>
        <mesh filename="package://mick_description/meshes/xarm7/visual/link4.STL"/>
      </geometry>
      <material name="White"/>
    </visual>
    <collision>
      <geometry>
        <mesh filename="package://mick_description/meshes/xarm7/visual/link4.STL"/>
      </geometry>
    </collision>
  </link>
  <joint name="other_joint4" type="revolute">
    <origin rpy="1.5708 0 0" xyz="0.0525 0 0"/>
    <parent link="other_link3"/>
    <child link="other_link4"/>
    <axis xyz="0 0 1"/>
    <limit effort="30" lower="-0.19198" upper="3.927" velocity="3.14"/>
    <dynamics damping="5" friction="1"/>
  </joint>
  <link name="other_link5">
    <inertial>
      <origin rpy="0 0 0" xyz="-0.00031 0.01558 -0.0253"/>
      <mass value="1.357"/>
      <inertia ixx="0.005396" ixy="-1.53E-05" ixz="-6.7E-07" iyy="0.005" iyz="0.00020544" izz="0.00138734"/>
    </inertial>
    <visual>
      <origin rpy="0 0 0" xyz="0 0 0"/>
      <geometry>
        <mesh filename="package://mick_description/meshes/xarm7/visual/link5.STL"/>
      </geometry>
      <material name="White"/>
    </visual>
    <collision>
      <geometry>
        <mesh filename="package://mick_description/meshes/xarm7/visual/link5.STL"/>
      </geometry>
    </collision>
  </link>
  <joint name="other_joint5" type="revolute">
    <origin rpy="1.5708 0 0" xyz="0.0775 -0.3425 0"/>
    <parent link="other_link4"/>
    <child link="other_link5"/>
    <axis xyz="0 0 1"/>
    <limit effort="30" lower="-6.283185307179586" upper="6.283185307179586" velocity="3.14"/>
    <dynamics damping="5" friction="1"/>
  </joint>
  <link name="other_link6">
    <inertial>
      <origin rpy="0 0 0" xyz="0.065 0.03336 0.02131"/>
      <mass value="1.362"/>
      <inertia ixx="0.0015057" ixy="0.000496735" ixz="-2.9968E-04" iyy="0.0019297" iyz="-1.5E-04" izz="0.0024"/>
    </inertial>
    <visual>
      <origin rpy="0 0 0" xyz="0 0 0"/>
      <geometry>
        <mesh filename="package://mick_description/meshes/xarm7/visual/link6.STL"/>
      </geometry>
      <material name="White"/>
    </visual>
    <collision>
      <geometry>
        <mesh filename="package://mick_description/meshes/xarm7/visual/link6.STL"/>
      </geometry>
    </collision>
  </link>
  <joint name="other_joint6" type="revolute">
    <origin rpy="1.5708 0 0" xyz="0 0 0"/>
    <parent link="other_link5"/>
    <child link="other_link6"/>
    <axis xyz="0 0 1"/>
    <limit effort="20" lower="-1.69297" upper="3.141592653589793" velocity="3.14"/>
    <dynamics damping="2" friction="1"/>
  </joint>
  <link name="other_link7">
    <inertial>
      <origin rpy="0 0 0" xyz="0 -0.00677 -0.01098"/>
      <mass value="0.17"/>
      <inertia ixx="9.3E-05" ixy="0.0" ixz="0.0" iyy="5.87E-05" iyz="3.6E-06" izz="1.32E-04"/>
    </inertial>
    <visual>
      <origin rpy="0 0 0" xyz="0 0 0"/>
      <geometry>
        <mesh filename="package://mick_description/meshes/xarm7/visual/link7.STL"/>
      </geometry>
      <material name="Silver"/>
    </visual>
    <collision>
      <geometry>
        <mesh filename="package://mick_description/meshes/xarm7/visual/link7.STL"/>
      </geometry>
    </collision>
  </link>
  <joint name="other_joint7" type="revolute">
    <origin rpy="-1.5708 0 0" xyz="0.076 0.097 0"/>
    <parent link="other_link6"/>
    <child link="other_link7"/>
    <axis xyz="0 0 1"/>
    <limit effort="20" lower="-6.283185307179586" upper="6.283185307179586" velocity="3.14"/>
    <dynamics damping="2" friction="1"/>
  </joint>
  <link name="other_link_eef"/>
  <joint name="other_joint_eef" type="fixed">
    <origin rpy="0 0 0" xyz="0 0 0"/>
    <parent link="other_link7"/>
    <child link="other_link_eef"/>
  </joint>
  <transmission name="other_tran1">
    <type>transmission_interface/SimpleTransmission</type>
    <joint name="other_joint1">
      <hardwareInterface>hardware_interface/PositionJointInterface</hardwareInterface>
    </joint>
    <actuator name="other_motor1">
      <hardwareInterface>hardware_interface/PositionJointInterface</hardwareInterface>
      <mechanicalReduction>100</mechanicalReduction>
    </actuator>
  </transmission>
  <transmission name="other_tran2">
    <type>transmission_interface/SimpleTransmission</type>
    <joint name="other_joint2">
      <hardwareInterface>hardware_interface/PositionJointInterface</hardwareInterface>
    </joint>
    <actuator name="other_motor2">
      <hardwareInterface>hardware_interface/PositionJointInterface</hardwareInterface>
      <mechanicalReduction>100</mechanicalReduction>
    </actuator>
  </transmission>
  <transmission name="other_tran3">
    <type>transmission_interface/SimpleTransmission</type>
    <joint name="other_joint3">
      <hardwareInterface>hardware_interface/PositionJointInterface</hardwareInterface>
    </joint>
    <actuator name="other_motor3">
      <hardwareInterface>hardware_interface/PositionJointInterface</hardwareInterface>
      <mechanicalReduction>100</mechanicalReduction>
    </actuator>
  </transmission>
  <transmission name="other_tran4">
    <type>transmission_interface/SimpleTransmission</type>
    <joint name="other_joint4">
      <hardwareInterface>hardware_interface/PositionJointInterface</hardwareInterface>
    </joint>
    <actuator name="other_motor3">
      <hardwareInterface>hardware_interface/PositionJointInterface</hardwareInterface>
      <mechanicalReduction>100</mechanicalReduction>
    </actuator>
  </transmission>
  <transmission name="other_tran5">
    <type>transmission_interface/SimpleTransmission</type>
    <joint name="other_joint5">
      <hardwareInterface>hardware_interface/PositionJointInterface</hardwareInterface>
    </joint>
    <actuator name="other_motor5">
      <hardwareInterface>hardware_interface/PositionJointInterface</hardwareInterface>
      <mechanicalReduction>100</mechanicalReduction>
    </actuator>
  </transmission>
  <transmission name="other_tran6">
    <type>transmission_interface/SimpleTransmission</type>
    <joint name="other_joint6">
      <hardwareInterface>hardware_interface/PositionJointInterface</hardwareInterface>
    </joint>
    <actuator name="other_motor6">
      <hardwareInterface>hardware_interface/PositionJointInterface</hardwareInterface>
      <mechanicalReduction>100</mechanicalReduction>
    </actuator>
  </transmission>
  <transmission name="other_tran7">
    <type>transmission_interface/SimpleTransmission</type>
    <joint name="other_joint7">
      <hardwareInterface>hardware_interface/PositionJointInterface</hardwareInterface>
    </joint>
    <actuator name="other_motor7">
      <hardwareInterface>hardware_interface/PositionJointInterface</hardwareInterface>
      <mechanicalReduction>100</mechanicalReduction>
    </actuator>
  </transmission>
  <gazebo reference="other_link_base">
    <selfCollide>true</selfCollide>
  </gazebo>
  <gazebo reference="other_link1">
    <selfCollide>true</selfCollide>
  </gazebo>
  <gazebo reference="other_link2">
    <selfCollide>true</selfCollide>
  </gazebo>
  <gazebo reference="other_link3">
    <selfCollide>true</selfCollide>
  </gazebo>
  <gazebo reference="other_link4">
    <selfCollide>true</selfCollide>
  </gazebo>
  <gazebo reference="other_link5">
    <selfCollide>true</selfCollide>
  </gazebo>
  <gazebo reference="other_link6">
    <selfCollide>true</selfCollide>
  </gazebo>
  <gazebo reference="other_link7">
    <selfCollide>true</selfCollide>
  </gazebo>
</robot>

